# [47장] 에러처리

## 📌 47.1 에러처리의 필요성
- 에러가 발생하지 않는 코드를 작성하는 건 불가능하며, 때문에 발생한 에러에 대해 적절한 대처를 해주어야 함
```jsx
console.log('[Start]');

foo(); // ReferenceError: foo is not defined
// 발생한 에러를 방치하면 프로그램은 강제 종료된다.

// 에러에 의해 프로그램이 강제 종료되어 아래 코드는 실행되지 않는다.
console.log('[End]');
```
- try~catch 문을 이용해 적절하게 대응하면 종료되지 않고 코드를 실행시킬 수 있음
```jsx
console.log('[Start]');

try {
  foo();
} catch (error) {
  console.error('[에러 발생]', error);
  // [에러 발생] ReferenceError: foo is not defined
}

// 발생한 에러에 적절한 대응을 하면 프로그램이 강제 종료되지 않는다.
console.log('[End]');
```

<br />

## 📌 47.2 try...catch...finally 문
### 🚀 대표적으로 에러처리하는 방법 2가지
1. 예외적인 상황이 발생하면 반환하는 값(null or -1)을 if문이나 옵셔널 체이닝 연산자 등을 통해 처리
2. 에러 코드를 미리 등록해두고, 에러 발생시 해당 코드로 점프시키는 방법

- try~catch~finally는 두번째 방법으로, 일반적으로 이 방법을 `에러 처리`라고 함
- try~catch~finally에서 finally는 생략이 가능하며, catch도 생략은 가능하나 catch문 없는 try는 의미가 없어서 생략하지 않음
```jsx
console.log('[Start]');

try {
  // 실행할 코드(에러가 발생할 가능성이 있는 코드)
  foo();
} catch (err) {
  // try 코드 블록에서 에러가 발생하면 이 코드 블록의 코드가 실행된다.
  // err에는 try 코드 블록에서 발생한 Error 객체가 전달된다.
  console.error(err); // ReferenceError: foo is not defined
} finally {
  // 에러 발생과 상관없이 반드시 한 번 실행된다.
  console.log('finally');
}

// try...catch...finally 문으로 에러를 처리하면 프로그램이 강제 종료되지 않는다.
console.log('[End]');
```

<br />

## 📌 47.3 Error 객체
- Error 생성자 함수는 에러 객체를 생성하며, 에러를 설명하는 에러 메시지를 인수로 전달 가능함
- 이렇게 생성된 에러 객체는 message 프로퍼티와 stack 프로퍼티를 갖음
  - message: Error 생성자 함수에 인수로 전달한 에러 메시지
  - stack: 에러를 발생시킨 콜스택의 호출 정보를 나타내는 문자열이며 디버깅 목적으로 사용됨
```jsx
const error = new Error('invalid');
```
- 생성자 함수의 종류는 아래와 같으며 이들이 생성한 에러 객체의 프로토타입은 모두 Error.prototype을 상속받음
> Error, SyntaxError, ReferenceError, TypeError, RangeError, URIError, EvalError  

<br />

## 📌 47.4 throw 문
- Error 생성자 함수로 에러 객체를 생성한다고 에러가 발생하는건 아님
- 에러 객체 생성과 에러 발생의 의미는 서로 다름!
```jsx
try {
  // 에러 객체를 생성한다고 에러가 발생하는 것은 아니다.
  new Error('something wrong');
} catch (error) {
  console.log(error);
}
```

- 에러를 발생시키려면 try 코드 블록에서 throw문으로 에러 객체를 던져야 함
- throw문의 표현식은 어떤 값이라도 상관 없으나 일반적으로 에러 객체를 지정됨
- error를 던지면 catch문에 에러 변수가 생성되고 던져진 에러 객체가 할당됨
```jsx
try {
  // 에러 객체를 던지면 catch 코드 블록이 실행되기 시작한다.
  throw new Error('something wrong');
} catch (error) {
  console.log(error);
}
```

<br />

## 📌 47.5 에러의 전파
- 에러는 호출자(caller) 방향으로 전파됨. 즉 콜 스택의 아래 방향으로 전파됨
```jsx
const foo = () => {
  throw Error('foo에서 발생한 에러'); // ④
};

const bar = () => {
  foo(); // ③
};

const baz = () => {
  bar(); // ②
};

try {
  baz(); // ①
} catch (err) {
  console.error(err);
}
```
<img src="https://github.com/user-attachments/assets/9a80d9ae-be47-49c4-b008-15435c099cc7" alt="" width="300" />

- 이처럼 throw된 에러를 캐치하지 않으면 호출자 방향으로 전파됨
- 이때 throw된 에러를 캐치하여 적절히 대응하면 프로그램을 강제 종료시키지 않고 코드의 실행 흐름을 복구할 수 있음

